[2021-04-23 17:01:03,808] {taskinstance.py:851} INFO - Dependencies all met for <TaskInstance: recent_played_ingestion.create_cluster_dataproc 2021-04-23T15:00:00+00:00 [queued]>
[2021-04-23 17:01:03,838] {taskinstance.py:851} INFO - Dependencies all met for <TaskInstance: recent_played_ingestion.create_cluster_dataproc 2021-04-23T15:00:00+00:00 [queued]>
[2021-04-23 17:01:03,840] {taskinstance.py:1042} INFO - 
--------------------------------------------------------------------------------
[2021-04-23 17:01:03,840] {taskinstance.py:1043} INFO - Starting attempt 3 of 3
[2021-04-23 17:01:03,841] {taskinstance.py:1044} INFO - 
--------------------------------------------------------------------------------
[2021-04-23 17:01:03,853] {taskinstance.py:1063} INFO - Executing <Task(DataprocCreateClusterOperator): create_cluster_dataproc> on 2021-04-23T15:00:00+00:00
[2021-04-23 17:01:03,860] {standard_task_runner.py:52} INFO - Started process 162 to run task
[2021-04-23 17:01:03,866] {standard_task_runner.py:76} INFO - Running: ['airflow', 'tasks', 'run', 'recent_played_ingestion', 'create_cluster_dataproc', '2021-04-23T15:00:00+00:00', '--job-id', '19', '--pool', 'default_pool', '--raw', '--subdir', 'DAGS_FOLDER/recent_played_ingestion.py', '--cfg-path', '/tmp/tmpwfvenfv2', '--error-file', '/tmp/tmpxdgg3ewd']
[2021-04-23 17:01:03,872] {standard_task_runner.py:77} INFO - Job 19: Subtask create_cluster_dataproc
[2021-04-23 17:01:03,959] {logging_mixin.py:104} INFO - Running <TaskInstance: recent_played_ingestion.create_cluster_dataproc 2021-04-23T15:00:00+00:00 [running]> on host 760ffd3d790b
[2021-04-23 17:01:04,053] {taskinstance.py:1257} INFO - Exporting the following env vars:
AIRFLOW_CTX_DAG_OWNER=airflow
AIRFLOW_CTX_DAG_ID=recent_played_ingestion
AIRFLOW_CTX_TASK_ID=create_cluster_dataproc
AIRFLOW_CTX_EXECUTION_DATE=2021-04-23T15:00:00+00:00
AIRFLOW_CTX_DAG_RUN_ID=scheduled__2021-04-23T15:00:00+00:00
[2021-04-23 17:01:04,061] {dataproc.py:603} INFO - Creating cluster: ephemeral-recent-played-spark-cluster-20210423
[2021-04-23 17:05:14,855] {taskinstance.py:1455} ERROR - 400 Initialization action failed. Failed action 'gs://spotimood-application-dev/pip_install.sh', see output in: gs://dataproc-staging-europe-west2-1086527958588-jcvhexoj/google-cloud-dataproc-metainfo/60dd9c05-9344-412c-a5f6-cf1476774180/ephemeral-recent-played-spark-cluster-20210423-m/dataproc-initialization-script-0_output
Traceback (most recent call last):
  File "/home/airflow/.local/lib/python3.6/site-packages/airflow/models/taskinstance.py", line 1112, in _run_raw_task
    self._prepare_and_execute_task_with_callbacks(context, task)
  File "/home/airflow/.local/lib/python3.6/site-packages/airflow/models/taskinstance.py", line 1285, in _prepare_and_execute_task_with_callbacks
    result = self._execute_task(context, task_copy)
  File "/home/airflow/.local/lib/python3.6/site-packages/airflow/models/taskinstance.py", line 1315, in _execute_task
    result = task_copy.execute(context=context)
  File "/home/airflow/.local/lib/python3.6/site-packages/airflow/providers/google/cloud/operators/dataproc.py", line 607, in execute
    cluster = self._create_cluster(hook)
  File "/home/airflow/.local/lib/python3.6/site-packages/airflow/providers/google/cloud/operators/dataproc.py", line 546, in _create_cluster
    cluster = operation.result()
  File "/home/airflow/.local/lib/python3.6/site-packages/google/api_core/future/polling.py", line 134, in result
    raise self._exception
google.api_core.exceptions.InvalidArgument: 400 Initialization action failed. Failed action 'gs://spotimood-application-dev/pip_install.sh', see output in: gs://dataproc-staging-europe-west2-1086527958588-jcvhexoj/google-cloud-dataproc-metainfo/60dd9c05-9344-412c-a5f6-cf1476774180/ephemeral-recent-played-spark-cluster-20210423-m/dataproc-initialization-script-0_output
[2021-04-23 17:05:15,046] {taskinstance.py:1503} INFO - Marking task as FAILED. dag_id=recent_played_ingestion, task_id=create_cluster_dataproc, execution_date=20210423T150000, start_date=20210423T170103, end_date=20210423T170514
[2021-04-23 17:05:15,424] {local_task_job.py:146} INFO - Task exited with return code 1
