[2021-04-25 12:33:09,803] {taskinstance.py:851} INFO - Dependencies all met for <TaskInstance: recent_played_ingestion.run_recent_played_classification_pypark 2021-04-25T09:00:00+00:00 [None]>
[2021-04-25 12:33:09,866] {taskinstance.py:851} INFO - Dependencies all met for <TaskInstance: recent_played_ingestion.run_recent_played_classification_pypark 2021-04-25T09:00:00+00:00 [None]>
[2021-04-25 12:33:09,872] {taskinstance.py:1042} INFO - 
--------------------------------------------------------------------------------
[2021-04-25 12:33:09,875] {taskinstance.py:1043} INFO - Starting attempt 15 of 15
[2021-04-25 12:33:09,878] {taskinstance.py:1044} INFO - 
--------------------------------------------------------------------------------
[2021-04-25 12:33:09,901] {taskinstance.py:1063} INFO - Executing <Task(DataprocSubmitPySparkJobOperator): run_recent_played_classification_pypark> on 2021-04-25T09:00:00+00:00
[2021-04-25 12:33:09,912] {standard_task_runner.py:52} INFO - Started process 718 to run task
[2021-04-25 12:33:09,923] {standard_task_runner.py:76} INFO - Running: ['airflow', 'tasks', 'run', 'recent_played_ingestion', 'run_recent_played_classification_pypark', '2021-04-25T09:00:00+00:00', '--job-id', '88', '--pool', 'default_pool', '--raw', '--subdir', 'DAGS_FOLDER/recent_played_ingestion.py', '--cfg-path', '/tmp/tmptcuqhkot', '--error-file', '/tmp/tmp55o6c19s']
[2021-04-25 12:33:09,941] {standard_task_runner.py:77} INFO - Job 88: Subtask run_recent_played_classification_pypark
[2021-04-25 12:33:10,046] {logging_mixin.py:104} INFO - Running <TaskInstance: recent_played_ingestion.run_recent_played_classification_pypark 2021-04-25T09:00:00+00:00 [running]> on host 67976f37379c
[2021-04-25 12:33:10,149] {taskinstance.py:1257} INFO - Exporting the following env vars:
AIRFLOW_CTX_DAG_OWNER=airflow
AIRFLOW_CTX_DAG_ID=recent_played_ingestion
AIRFLOW_CTX_TASK_ID=run_recent_played_classification_pypark
AIRFLOW_CTX_EXECUTION_DATE=2021-04-25T09:00:00+00:00
AIRFLOW_CTX_DAG_RUN_ID=scheduled__2021-04-25T09:00:00+00:00
[2021-04-25 12:33:10,158] {dataproc.py:981} INFO - Submitting pyspark_job job run_recent_played_classification_pypark_20210425_47a85186
[2021-04-25 12:33:10,690] {taskinstance.py:1455} ERROR - 404 Not found: Cluster projects/spotimood-dev/regions/europe-west2/clusters/ephemeral-recent-played-spark-cluster-20210425
Traceback (most recent call last):
  File "/home/airflow/.local/lib/python3.6/site-packages/google/api_core/grpc_helpers.py", line 73, in error_remapped_callable
    return callable_(*args, **kwargs)
  File "/home/airflow/.local/lib/python3.6/site-packages/grpc/_channel.py", line 923, in __call__
    return _end_unary_response_blocking(state, call, False, None)
  File "/home/airflow/.local/lib/python3.6/site-packages/grpc/_channel.py", line 826, in _end_unary_response_blocking
    raise _InactiveRpcError(state)
grpc._channel._InactiveRpcError: <_InactiveRpcError of RPC that terminated with:
	status = StatusCode.NOT_FOUND
	details = "Not found: Cluster projects/spotimood-dev/regions/europe-west2/clusters/ephemeral-recent-played-spark-cluster-20210425"
	debug_error_string = "{"created":"@1619353990.689091400","description":"Error received from peer ipv4:216.58.215.170:443","file":"src/core/lib/surface/call.cc","file_line":1067,"grpc_message":"Not found: Cluster projects/spotimood-dev/regions/europe-west2/clusters/ephemeral-recent-played-spark-cluster-20210425","grpc_status":5}"
>

The above exception was the direct cause of the following exception:

Traceback (most recent call last):
  File "/home/airflow/.local/lib/python3.6/site-packages/airflow/models/taskinstance.py", line 1112, in _run_raw_task
    self._prepare_and_execute_task_with_callbacks(context, task)
  File "/home/airflow/.local/lib/python3.6/site-packages/airflow/models/taskinstance.py", line 1285, in _prepare_and_execute_task_with_callbacks
    result = self._execute_task(context, task_copy)
  File "/home/airflow/.local/lib/python3.6/site-packages/airflow/models/taskinstance.py", line 1315, in _execute_task
    result = task_copy.execute(context=context)
  File "/home/airflow/.local/lib/python3.6/site-packages/airflow/providers/google/cloud/operators/dataproc.py", line 1545, in execute
    super().execute(context)
  File "/home/airflow/.local/lib/python3.6/site-packages/airflow/providers/google/cloud/operators/dataproc.py", line 983, in execute
    project_id=self.project_id, job=self.job["job"], location=self.region
  File "/home/airflow/.local/lib/python3.6/site-packages/airflow/providers/google/common/hooks/base_google.py", line 425, in inner_wrapper
    return func(self, *args, **kwargs)
  File "/home/airflow/.local/lib/python3.6/site-packages/airflow/providers/google/cloud/hooks/dataproc.py", line 819, in submit_job
    metadata=metadata,
  File "/home/airflow/.local/lib/python3.6/site-packages/google/cloud/dataproc_v1beta2/gapic/job_controller_client.py", line 279, in submit_job
    request, retry=retry, timeout=timeout, metadata=metadata
  File "/home/airflow/.local/lib/python3.6/site-packages/google/api_core/gapic_v1/method.py", line 145, in __call__
    return wrapped_func(*args, **kwargs)
  File "/home/airflow/.local/lib/python3.6/site-packages/google/api_core/grpc_helpers.py", line 75, in error_remapped_callable
    six.raise_from(exceptions.from_grpc_error(exc), exc)
  File "<string>", line 3, in raise_from
google.api_core.exceptions.NotFound: 404 Not found: Cluster projects/spotimood-dev/regions/europe-west2/clusters/ephemeral-recent-played-spark-cluster-20210425
[2021-04-25 12:33:10,695] {taskinstance.py:1503} INFO - Marking task as FAILED. dag_id=recent_played_ingestion, task_id=run_recent_played_classification_pypark, execution_date=20210425T090000, start_date=20210425T123309, end_date=20210425T123310
[2021-04-25 12:33:10,731] {local_task_job.py:146} INFO - Task exited with return code 1
