[2021-04-25 09:40:15,640] {taskinstance.py:851} INFO - Dependencies all met for <TaskInstance: recent_played_ingestion.create_cluster_dataproc 2021-04-25T08:00:00+00:00 [queued]>
[2021-04-25 09:40:15,681] {taskinstance.py:851} INFO - Dependencies all met for <TaskInstance: recent_played_ingestion.create_cluster_dataproc 2021-04-25T08:00:00+00:00 [queued]>
[2021-04-25 09:40:15,683] {taskinstance.py:1042} INFO - 
--------------------------------------------------------------------------------
[2021-04-25 09:40:15,684] {taskinstance.py:1043} INFO - Starting attempt 1 of 1
[2021-04-25 09:40:15,685] {taskinstance.py:1044} INFO - 
--------------------------------------------------------------------------------
[2021-04-25 09:40:15,705] {taskinstance.py:1063} INFO - Executing <Task(DataprocCreateClusterOperator): create_cluster_dataproc> on 2021-04-25T08:00:00+00:00
[2021-04-25 09:40:15,714] {standard_task_runner.py:52} INFO - Started process 40 to run task
[2021-04-25 09:40:15,722] {standard_task_runner.py:76} INFO - Running: ['airflow', 'tasks', 'run', 'recent_played_ingestion', 'create_cluster_dataproc', '2021-04-25T08:00:00+00:00', '--job-id', '54', '--pool', 'default_pool', '--raw', '--subdir', 'DAGS_FOLDER/recent_played_ingestion.py', '--cfg-path', '/tmp/tmptz6cpim4', '--error-file', '/tmp/tmpprcuz5zy']
[2021-04-25 09:40:15,727] {standard_task_runner.py:77} INFO - Job 54: Subtask create_cluster_dataproc
[2021-04-25 09:40:15,810] {logging_mixin.py:104} INFO - Running <TaskInstance: recent_played_ingestion.create_cluster_dataproc 2021-04-25T08:00:00+00:00 [running]> on host 67976f37379c
[2021-04-25 09:40:15,948] {taskinstance.py:1257} INFO - Exporting the following env vars:
AIRFLOW_CTX_DAG_OWNER=airflow
AIRFLOW_CTX_DAG_ID=recent_played_ingestion
AIRFLOW_CTX_TASK_ID=create_cluster_dataproc
AIRFLOW_CTX_EXECUTION_DATE=2021-04-25T08:00:00+00:00
AIRFLOW_CTX_DAG_RUN_ID=scheduled__2021-04-25T08:00:00+00:00
[2021-04-25 09:40:15,953] {dataproc.py:603} INFO - Creating cluster: ephemeral-recent-played-spark-cluster-20210425
[2021-04-25 09:44:42,649] {taskinstance.py:1455} ERROR - 400 Initialization action failed. Failed action 'gs://spotimood-application-dev/pip_install.sh', see output in: gs://dataproc-staging-europe-west2-1086527958588-jcvhexoj/google-cloud-dataproc-metainfo/85b297ed-afdc-4283-9c25-3119f494e95a/ephemeral-recent-played-spark-cluster-20210425-m/dataproc-initialization-script-0_output
Traceback (most recent call last):
  File "/home/airflow/.local/lib/python3.6/site-packages/airflow/models/taskinstance.py", line 1112, in _run_raw_task
    self._prepare_and_execute_task_with_callbacks(context, task)
  File "/home/airflow/.local/lib/python3.6/site-packages/airflow/models/taskinstance.py", line 1285, in _prepare_and_execute_task_with_callbacks
    result = self._execute_task(context, task_copy)
  File "/home/airflow/.local/lib/python3.6/site-packages/airflow/models/taskinstance.py", line 1315, in _execute_task
    result = task_copy.execute(context=context)
  File "/home/airflow/.local/lib/python3.6/site-packages/airflow/providers/google/cloud/operators/dataproc.py", line 607, in execute
    cluster = self._create_cluster(hook)
  File "/home/airflow/.local/lib/python3.6/site-packages/airflow/providers/google/cloud/operators/dataproc.py", line 546, in _create_cluster
    cluster = operation.result()
  File "/home/airflow/.local/lib/python3.6/site-packages/google/api_core/future/polling.py", line 134, in result
    raise self._exception
google.api_core.exceptions.InvalidArgument: 400 Initialization action failed. Failed action 'gs://spotimood-application-dev/pip_install.sh', see output in: gs://dataproc-staging-europe-west2-1086527958588-jcvhexoj/google-cloud-dataproc-metainfo/85b297ed-afdc-4283-9c25-3119f494e95a/ephemeral-recent-played-spark-cluster-20210425-m/dataproc-initialization-script-0_output
[2021-04-25 09:44:42,688] {taskinstance.py:1503} INFO - Marking task as FAILED. dag_id=recent_played_ingestion, task_id=create_cluster_dataproc, execution_date=20210425T080000, start_date=20210425T094015, end_date=20210425T094442
[2021-04-25 09:44:42,904] {local_task_job.py:146} INFO - Task exited with return code 1
